---
layout: post
title: Java异常处理
abbrlink: 79ca873aba1f45e18f955a7e11656bc2
tags:
  - java
categories:
  - JDK
  - 基础篇
date: 1745339269489
updated: 1746417415799
---

Java 异常、断言

<!-- more -->

***

## 什么是异常？

在 Java 编程中，异常(exception)是指在程序执行过程中发生的意外情况，它会中断正常的指令流。例如，当你尝试打开一个不存在的文件，或者访问一个空对象的成员时，就会发生异常。

异常处理是 Java 提供的一种机制，用于优雅地处理这些运行时错误，而不是让程序直接崩溃。

## Java 异常体系

Java 的异常体系是一个层次分明的结构，所有异常和错误都继承自`java.lang.Throwable`类。

```sh
Throwable (可抛出)
├── Error (错误)
│   ├── VirtualMachineError
│   │   ├── OutOfMemoryError
│   │   └── StackOverflowError
│   └── ...
├── Exception (异常)
│   ├── RuntimeException (运行时异常/非受检异常)
│   │   ├── NullPointerException
│   │   ├── IndexOutOfBoundsException
│   │   ├── IllegalArgumentException
│   │   └── ...
│   └── 其他受检异常 (Checked Exceptions)
│       ├── IOException
│       ├── SQLException
│       └── ...
```

### Throwable 类

Throwable 是 Java 语言中所有错误(Error)和异常(Exception)的超类，位于异常体系的最顶端。它包含了线程创建时线程执行堆栈的快照，并提供了以下重要功能：

1. 异常信息存储：保存异常的描述信息

2. 异常原因追踪：通过`getCause()`方法获取引发当前异常的原因

3. 堆栈跟踪：提供`printStackTrace()`等方法用于获取堆栈跟踪信息

Throwable 类的主要方法包括：

1. `String getMessage()`：返回异常的描述信息
2. `String toString()`：返回异常的详细信息
3. `void printStackTrace()`：打印异常的堆栈跟踪信息
4. `Throwable getCause()`：获取导致此异常的原因

### Error (错误)

- 表示严重的系统级问题，通常不应被应用程序捕获
- 由 JVM 抛出，表示 JVM 资源耗尽或其他无法恢复的故障
- 示例：`OutOfMemoryError`, `StackOverflowError`

### Exception (异常)

- 表示程序可以处理的异常情况
- 分为两大类：

  **a. RuntimeException (运行时异常/非受检异常)**

  - 由程序逻辑错误引起，不强制要求捕获或声明,代码可以选择处理或不处理
  - 常见 RuntimeException：
    - `NullPointerException`：空指针异常
    - `ArrayIndexOutOfBoundsException`：数组越界异常
    - `ClassCastException`：类型转换异常
    - `IllegalArgumentException`：非法参数异常

  **b. 受检异常 (Checked Exceptions)**

  - 必须被捕获或在方法签名中声明，否则代码无法编译通过
  - 表示程序可以预期并可能恢复的情况
  - 常见 Checked Exception：
    - `IOException`：IO 操作异常
    - `SQLException`：数据库操作异常
    - `ClassNotFoundException`：类未找到异常
    - `InterruptedException`：线程中断异常

## 异常处理的基本语法

Java 提供了 `try-catch-finally` 结构来处理异常，其基本语法如下：

```java
try {
    // 可能抛出异常的代码
} catch (ExceptionType1 e1) {
    // 处理 ExceptionType1 类型的异常
} catch (ExceptionType2 e2) {
    // 处理 ExceptionType2 类型的异常
} finally {
    // 无论是否发生异常都会执行的代码
}
```

### try 块

- 包含可能抛出异常的代码
- 一旦发生异常，try 块中剩余的代码将不会执行
- 可以包含多个可能抛出异常的语句

### catch 块

- 捕获并处理特定类型的异常

- 可以有多个 catch 块，但应该按照从具体到一般的顺序排列（即子类在前，父类在后）

- 每个 catch 块处理一种特定类型的异常

- 可以使用 `|` 运算符捕获多种异常（Java 7+）：

  ```java
  catch (IOException | SQLException e) {
      // 处理 IO 或 SQL 异常
  }
  ```

### finally 块

- 无论是否发生异常都会执行的代码块
- 常用于释放资源（如关闭文件、数据库连接等）
- 即使 try 或 catch 块中有 return 语句，finally 块也会执行
- 在 System.exit() 情况下不会执行
- **不要在 `finally` 中使用 `return`**，因为它会：
  - 覆盖 `try/catch` 的返回值
  - 吞掉异常，导致难以调试的问题

### 示例代码

```java
public class ExceptionDemo {
    public static void main(String[] args) {
        try {
            int[] numbers = {1, 2, 3};
            System.out.println(numbers[5]); // 这将抛出ArrayIndexOutOfBoundsException
        } catch (ArrayIndexOutOfBoundsException e) {
            System.out.println("数组索引越界: " + e.getMessage());
        } catch (Exception e) {
            System.out.println("发生了其他异常: " + e.getMessage());
        } finally {
            System.out.println("这段代码总是会执行");
        }

        System.out.println("程序继续执行...");
    }
}
```

### throws 关键字

- 如果一个方法可能会抛出检查型异常但不处理它，可以使用`throws`关键字声明该方法可能抛出的异常类型

- 语法：`void method() throws ExceptionType1, ExceptionType2 {...}`

- 调用该方法时必须处理这些异常或继续向上抛出

  ```java
  public void readFile(String fileName) throws FileNotFoundException {
      FileReader file = new FileReader(fileName);
      // ...
  }
  ```

### throw 关键字

- 用于显式主动抛出一个异常对象
- 语法：`throw new ExceptionType("message");`
- 可以抛出任何 Throwable 或其子类的实例

```java
public void checkAge(int age) {
    if (age < 18) {
        throw new ArithmeticException("年龄不足18岁");
    } else {
        System.out.println("欢迎访问");
    }
}
```

## 自定义异常

你可以创建自己的异常类来满足特定需求：

```java
class MyException extends Exception {
    public MyException(String message) {
        super(message);
    }
}

public class TestCustomException {
    static void validate(int age) throws MyException {
        if (age < 18) {
            throw new MyException("年龄不足");
        } else {
            System.out.println("欢迎");
        }
    }

    public static void main(String[] args) {
        try {
            validate(13);
        } catch (MyException e) {
            System.out.println("捕获自定义异常: " + e.getMessage());
        }
    }
}
```

## finally 块中的 return 问题

在 Java 异常处理中，`finally` 块通常用于执行必须完成的清理工作（如关闭文件、释放资源等）。然而，如果在 `finally` 块中使用 `return`，可能会产生一些**反直觉的行为**，因为它会覆盖 `try` 或 `catch` 块中的返回值，甚至**吞掉异常**。

### finally 覆盖 try 的返回值

**示例 1：finally 覆盖 try 的返回值**

```java
public class FinallyReturnDemo {
    public static void main(String[] args) {
        System.out.println(getValue()); // 输出 2，而不是 1！
    }

    public static int getValue() {
        try {
            return 1; // 这个返回值会被 finally 覆盖
        } finally {
            return 2; // 最终返回的是 2
        }
    }
}
```

**结论：**

- **`finally` 中的 `return` 会覆盖 `try` 或 `catch` 中的 `return`**，导致方法最终返回 `finally` 的值。
- 这是一种**不推荐的做法**，因为它会掩盖 `try` 或 `catch` 的预期返回值，可能导致逻辑错误。

### finally 吞掉 try/catch 的异常

**示例 2：finally 吞掉异常**

```java
public class FinallySwallowException {
    public static void main(String[] args) {
        System.out.println(divide(10, 0)); // 输出 "finally return"，而不是抛出异常！
    }

    public static String divide(int a, int b) {
        try {
            return String.valueOf(a / b); // 这里会抛出 ArithmeticException
        } catch (ArithmeticException e) {
            throw new RuntimeException("计算错误"); // 这个异常会被 finally 吞掉
        } finally {
            return "finally return"; // 最终返回这个值，异常被忽略
        }
    }
}
```

**结论：**

- **如果 `finally` 中有 `return`，它会覆盖 `try` 或 `catch` 中的返回值，并且会吞掉任何未处理的异常**。
- 这可能导致程序**静默失败**（silent failure），即异常被忽略，但程序仍然继续执行，可能导致更严重的错误。

### finally 修改引用类型返回值

**示例 3：finally 修改引用类型返回值**

```java
public class FinallyModifyReference {
    public static void main(String[] args) {
        StringBuilder sb = getStringBuilder();
        System.out.println(sb); // 输出 "Hello finally"
    }

    public static StringBuilder getStringBuilder() {
        StringBuilder sb = new StringBuilder("Hello");
        try {
            return sb; // 返回 sb 的引用
        } finally {
            sb.append(" finally"); // 修改 sb 的内容
        }
    }
}
```

**结论：**

- 如果 `finally` 修改的是**引用类型（如对象、数组、集合等）**，即使 `try` 已经返回了引用，`finally` 仍然可以修改其内容。
- 但对于**基本类型（如 `int`、`double`）**，`finally` 无法修改 `try` 返回的值。

### 总结

| 情况                   | 行为                       | 是否推荐    |
| -------------------- | ------------------------ | ------- |
| `finally` 有 `return` | 覆盖 `try/catch` 的返回值，吞掉异常 | ❌ 不推荐   |
| `finally` 修改引用类型     | 会影响 `try` 返回的对象          | ⚠️ 谨慎使用 |
| `finally` 无 `return` | 正常执行清理，不影响返回值            | ✅ 推荐    |

## 异常链(Chained Exceptions)

### 什么是异常链

异常链是指一个异常引发另一个异常的情况。Java 允许我们将原始异常（根本原因）与新的异常关联起来，形成异常链。这在多层架构的应用程序中特别有用，可以帮助我们追踪异常的完整传播路径。

### 异常链的实现方式

Java 的`Throwable`类提供了以下方法来支持异常链：

- `Throwable(Throwable cause)` - 构造器，接受一个原因异常
- `Throwable(String message, Throwable cause)` - 构造器，接受消息和原因异常
- `Throwable initCause(Throwable cause)` - 设置原始异常（只能在异常未被抛出前调用一次）
- `Throwable getCause()` - 获取原因异常
- `Throwable.printStackTrace()`：打印完整的异常链信息

### 异常链示例

```java
public class ChainedExceptionDemo {
    public static void main(String[] args) {
        try {
            method1();
        } catch (Exception e) {
            // 打印当前异常信息
            System.out.println("捕获的异常: " + e);

            // 获取并打印原因异常
            Throwable cause = e.getCause();
            System.out.println("根本原因: " + cause);

            // 打印完整的堆栈跟踪
            e.printStackTrace();
        }
    }

    static void method1() throws Exception {
        try {
            method2();
        } catch (NullPointerException e) {
            // 创建一个新异常，并将原始异常作为原因
            throw new Exception("method1中发生错误", e);
        }
    }

    static void method2() {
        // 模拟一个空指针异常
        String str = null;
        System.out.println(str.length());
    }
}
```

**输出示例**：

```markdown
捕获的异常: java.lang.Exception: method1中发生错误
根本原因: java.lang.NullPointerException: Cannot invoke "String.length()" because "str" is null
java.lang.Exception: method1中发生错误
	at ChainedExceptionDemo.method1(Main.java:68)
	at ChainedExceptionDemo.main(Main.java:49)
Caused by: java.lang.NullPointerException: Cannot invoke "String.length()" because "str" is null
	at ChainedExceptionDemo.method2(Main.java:75)
	at ChainedExceptionDemo.method1(Main.java:65)
	... 1 more
```

## try-with-resources 语句

Java 7 引入了 try-with-resources 语句，用于自动管理资源（如流、连接等）：

```java
try (FileReader fr = new FileReader("test.txt");
     BufferedReader br = new BufferedReader(fr)) {
    // 使用资源
} catch (IOException e) {
    e.printStackTrace();
}
// 资源会自动关闭，无需显式调用close()
```

## Suppressed 异常

Suppressed 异常（被抑制的异常）是 Java 7 引入的一个重要异常处理机制，主要与 `try-with-resources` 语句和 `Throwable.addSuppressed()` 方法相关。它解决了在异常处理过程中可能丢失次要异常的问题。

当多个异常同时发生时（例如主异常和资源关闭时抛出的异常），Java 会将非主要的异常附加到主异常上作为"被抑制的异常"，而不是简单地丢弃它们。这样所有相关的异常信息都能被保留下来。

### 产生 Suppressed 异常的典型场景

1. **try-with-resources 语句：**

   ```java
   try (InputStream in = new FileInputStream("file.txt")) {
       // 使用资源时抛出主异常
       throw new RuntimeException("主异常");
   }
   // 如果资源关闭时也抛出异常，它会被作为suppressed异常
   ```

2. 手动添加：

   ```java
   try {
       // 某些操作
   } catch (Exception primary) {
       try {
           // 清理操作抛出次要异常
       } catch (Exception secondary) {
           primary.addSuppressed(secondary);  // 手动添加为suppressed异常
       }
       throw primary;
   }
   ```

### 访问 Suppressed 异常的方法

`Throwable`类提供了以下方法来处理 Suppressed 异常：

- `addSuppressed(Throwable exception)` - 添加一个被抑制的异常
- `Throwable[] getSuppressed()` - 获取所有被抑制的异常

### Suppressed 异常示例

```java
public class SuppressedExceptionDemo {
    public static void main(String[] args) {
        try {
            tryWithResources();
        } catch (Exception e) {
            System.out.println("主异常: " + e.getMessage());
            for (Throwable suppressed : e.getSuppressed()) {
                System.out.println("被抑制的异常: " + suppressed.getMessage());
            }
        }
    }

    static void tryWithResources() throws Exception {
        try (Resource resource = new Resource()) {
            throw new Exception("主异常 - 操作失败");
        }
    }
}

class Resource implements AutoCloseable {
    @Override
    public void close() throws Exception {
        throw new Exception("被抑制的异常 - 关闭资源失败");
    }
}
```

**输出结果：**

```
主异常: 主异常 - 操作失败
被抑制的异常: 被抑制的异常 - 关闭资源失败
```

## 断言（Assertion）

Java 中的断言（Assertion）是一种用于在开发和测试阶段验证程序内部逻辑的机制，帮助开发者快速发现代码中的错误假设。

### 基本语法

- **简单形式**：`assert condition;`\
  当`condition`为`false`时，抛出`AssertionError`。

- **带详情形式**：`assert condition : expression;`\
  当条件失败时，`expression`的结果会作为错误信息（可以是任何对象或基本类型）。

- **示例**：

  ```java
  assert x > 0;  // 若x<=0，抛出AssertionError
  assert list.size() == 0 : "列表应该为空，但当前大小是：" + list.size();
  ```

### 启用断言

默认情况下，断言是禁用的。需通过以下方式启用：

- **命令行**：添加`-ea`或`-enableassertions`参数：
  ```bash
  java -ea MyClass
  ```
- **IDE 配置**（如 IntelliJ/Eclipse）：在运行配置的 VM 参数中添加`-ea`。

### 适用场景

- **调试假设条件**：验证不应出现的情况（如不可能的分支、数据范围等）。
- **内部不变性检查**：如方法执行后的状态是否符合预期。
- **私有方法参数验证**：在私有方法中检查参数合法性（公共方法建议用异常）。

**示例**：

```java
private void process(int value) {
    assert value >= 0 : "值不能为负数";
    // 后续逻辑...
}
```

### 断言 vs 异常

| **断言**               | **异常**                              |
| -------------------- | ----------------------------------- |
| 用于调试阶段的“不可能发生”的情况    | 处理运行时可能出现的预期错误                      |
| 默认禁用，适合内部检查          | 始终启用，适合对外部输入的校验                     |
| 失败抛出`AssertionError` | 抛出特定异常（如`IllegalArgumentException`） |

### 示例代码

```java
public class AssertionDemo {
    public static void main(String[] args) {
        int age = -5;
        // 检查年龄是否为正
        assert age >= 0 : "年龄不能为负数: " + age;
        System.out.println("年龄是：" + age);
    }
}
```

**输出（启用断言时）**：

```
Exception in thread "main" java.lang.AssertionError: 年龄不能为负数: -5
```

### 注意事项

- **不要用于公共方法的参数校验**：公共方法可能接收外部输入，需用异常处理非法参数。
- **避免副作用**：断言条件中不应修改程序状态，否则禁用断言时行为不一致。
- **生产环境慎用**：断言通常在生产环境中禁用，不可依赖其处理关键错误。
